{"uuid": "4ba9cc08-67cb-465e-8484-6701a0ab589e", "children": ["92677d16-87de-4649-9129-702bdaadb8d9", "632342ea-eb70-4f77-b379-ae0cc523ed22", "fab6bcbc-c467-4c39-84ab-7c5ec41a93f0", "7e0cc654-c806-4a03-92d4-9d62fa68272d", "fa8783ef-b88b-4aaf-bcb1-5a7f68a67a4b"], "befores": [{"name": "xunit_setup_class_fixture_TestMall", "status": "broken", "statusDetails": {"message": "selenium.common.exceptions.WebDriverException: Message: An unknown server-side error occurred while processing the command. Original error: Could not find a connected Android device in 20022ms.\n\n", "trace": "  File \"C:\\Users\\Administrator\\AppData\\Local\\Programs\\Python\\Python38\\lib\\site-packages\\pluggy\\callers.py\", line 187, in _multicall\n    res = hook_impl.function(*args)\n  File \"C:\\Users\\Administrator\\AppData\\Local\\Programs\\Python\\Python38\\lib\\site-packages\\_pytest\\fixtures.py\", line 1126, in pytest_fixture_setup\n    result = call_fixture_func(fixturefunc, request, kwargs)\n  File \"C:\\Users\\Administrator\\AppData\\Local\\Programs\\Python\\Python38\\lib\\site-packages\\_pytest\\fixtures.py\", line 925, in call_fixture_func\n    fixture_result = next(generator)\n  File \"C:\\Users\\Administrator\\AppData\\Local\\Programs\\Python\\Python38\\lib\\site-packages\\_pytest\\python.py\", line 811, in xunit_setup_class_fixture\n    _call_with_optional_argument(func, self.obj)\n  File \"C:\\Users\\Administrator\\AppData\\Local\\Programs\\Python\\Python38\\lib\\site-packages\\_pytest\\python.py\", line 739, in _call_with_optional_argument\n    func(arg)\n  File \"D:\\gitfile\\uiautomation\\zikaow\\TestCase\\test_booksmall.py\", line 15, in setup_class\n    self.testDriver = App().restart().main()\n  File \"D:\\gitfile\\uiautomation\\zikaow\\Page\\app.py\", line 42, in restart\n    self._driver = webdriver.Remote(\"http://127.0.0.1:4723/wd/hub\", desir_cap)\n  File \"C:\\Users\\Administrator\\AppData\\Local\\Programs\\Python\\Python38\\lib\\site-packages\\appium\\webdriver\\webdriver.py\", line 151, in __init__\n    super().__init__(\n  File \"C:\\Users\\Administrator\\AppData\\Local\\Programs\\Python\\Python38\\lib\\site-packages\\selenium\\webdriver\\remote\\webdriver.py\", line 157, in __init__\n    self.start_session(capabilities, browser_profile)\n  File \"C:\\Users\\Administrator\\AppData\\Local\\Programs\\Python\\Python38\\lib\\site-packages\\appium\\webdriver\\webdriver.py\", line 225, in start_session\n    response = self.execute(RemoteCommand.NEW_SESSION, parameters)\n  File \"C:\\Users\\Administrator\\AppData\\Local\\Programs\\Python\\Python38\\lib\\site-packages\\selenium\\webdriver\\remote\\webdriver.py\", line 321, in execute\n    self.error_handler.check_response(response)\n  File \"C:\\Users\\Administrator\\AppData\\Local\\Programs\\Python\\Python38\\lib\\site-packages\\selenium\\webdriver\\remote\\errorhandler.py\", line 242, in check_response\n    raise exception_class(message, screen, stacktrace)\n"}, "start": 1622799190439, "stop": 1622799210578}], "start": 1622799190439, "stop": 1622799210903}